<?xml version="1.0"?>
<!-- created with Phobos 0.8 -->
<!-- right joint and link position!!!!!!! finally!!! -->
  <robot name="legs_testMove">
      <link name="base_link">
      <inertial>
        <origin rpy="0 0 0" xyz="0 0 0"/>
        <mass value="1.0"/>
        <inertia ixx="0.01" ixy="0.01" ixz="0.01" iyy="0.01" iyz="0.01" izz="0.01"/>
      </inertial>
      <visual>
        <origin rpy="0 0 0" xyz="0 0 0"/>
        <geometry>
          <box size="0.01 0.01 0.01"/>
        </geometry>
        <material name="color_01"/>
      </visual>
    </link>  
    
    <link name="link_shoulder_l">
      <inertial>
        <origin rpy="0 0 0" xyz="0 0 0"/>
        <mass value="2.0"/>
        <inertia ixx="0" ixy="0" ixz="0" iyy="0" iyz="0" izz="0"/>
      </inertial>   
      <visual name="shoulder_l">
        <origin xyz="0.17547 0 0" rpy="1.5708 0 0"/>
        <!-- <origin xyz="0.08415 0 0" rpy="1.5708 0 0"/> -->
        <geometry>
          <mesh filename="meshes/shoulder_l.obj" scale="1.0 1.0 1.0"/>
        </geometry>
        <material name="color_01"/>
      </visual>
      <collision name="co_shoulder_l">
        <origin xyz="0.17547 0 0" rpy="1.5708 0 0"/>
        <geometry>
          <mesh filename="meshes/shoulder_l.obj" scale="1.0 1.0 1.0"/>
        </geometry>
      </collision>
    </link>
    
    <link name="link_arm_l_01">
      <inertial>
        <origin rpy="0 0 0" xyz="0 0 0"/>
        <mass value="4.0"/>
        <inertia ixx="0" ixy="0" ixz="0" iyy="0" iyz="0" izz="0"/>
      </inertial>  
      <visual name="arm_l_01">
        <origin xyz="0.175 0 0.02" rpy="0 0 0"/>
        <!-- <origin xyz="0.09523 -0.00406 -0.01136" rpy="0 0 0"/> -->
        <geometry>
          <mesh filename="meshes/arm_l_01.obj" scale="1.0 1.0 1.0"/>
        </geometry>
        <material name="color_03"/>
      </visual>
      <collision name="co_arm_l_01">
        <origin xyz="0.175 0 0.02" rpy="1.5708 0 0"/>
        <geometry>
          <mesh filename="meshes/arm_l_01.obj" scale="1.0 1.0 1.0"/>
        </geometry>
      </collision>
    </link>

    <link name="link_arm_l_02">
      <inertial>
        <origin rpy="0 0 0" xyz="0 0 0"/>
        <mass value="5.0"/>
        <inertia ixx="0" ixy="0" ixz="0" iyy="0" iyz="0" izz="0"/>
      </inertial>  
      <visual name="arm_l_02">
        <origin xyz="-0.05 -0.10815 0.21758" rpy="0 0 0"/>
        <!-- <origin xyz="-0.00153 -0.09056 -0.05436" rpy="0 0 0"/> -->
        <geometry>
          <mesh filename="meshes/arm_l_02.obj" scale="1.0 1.0 1.0"/>
        </geometry>
        <material name="color_04"/>
      </visual>
      <collision name="co_arm_l_02">
        <origin xyz="-0.05 -0.10815 0.21758" rpy="1.5708 0 0"/>
        <geometry>
          <mesh filename="meshes/arm_l_02.obj" scale="1.0 1.0 1.0"/>
        </geometry>
      </collision>
    </link>

    <link name="link_arm_l_03">
      <inertial>
        <origin rpy="0 0 0" xyz="0 0 0"/>
        <mass value="5.0"/>
        <inertia ixx="0" ixy="0" ixz="0" iyy="0" iyz="0" izz="0"/>
      </inertial> 
      <visual name="arm_l_03">
        <origin xyz="-0.02 0.01137 0.235" rpy="0 0 0"/>
        <!-- <origin xyz="0.01526 -0.09395 0.00264" rpy="1.5708 0 0"/> -->
        <geometry>
          <mesh filename="meshes/arm_l_03.obj" scale="1.0 1.0 1.0"/>
        </geometry>
        <material name="color_01"/>
      </visual>
      <collision name="co_arm_l_03">
        <origin xyz="-0.02 0.01137 0.235" rpy="1.5708 0 0"/>
        <geometry>
          <mesh filename="meshes/arm_l_03.obj" scale="1.0 1.0 1.0"/>
        </geometry>
      </collision>
    </link>

    <link name="link_hand_l">
      <inertial>
        <origin rpy="0 0 0" xyz="0 0 0"/>
        <mass value="1.0"/>
        <inertia ixx="0" ixy="0" ixz="0" iyy="0" iyz="0" izz="0"/>
      </inertial> 
      <visual name="hand_l">
        <origin xyz="-0.10738 0 0.075" rpy="0 0 0"/>
        <!-- <origin xyz="-0.06739 0.03449 0" rpy="1.5708 0 0"/> -->
        <geometry>
          <mesh filename="meshes/hand_l.obj" scale="1.0 1.0 1.0"/>
        </geometry>
        <material name="color_04"/>
      </visual>
      <collision name="co_hand_l">
        <origin xyz="-0.10738 0 0.075" rpy="1.5708 0 0"/>
        <geometry>
          <mesh filename="meshes/hand_l.obj" scale="1.0 1.0 1.0"/>
        </geometry>
      </collision>
    </link>

    <link name="link_shoulder_r">
      <inertial>
        <origin rpy="0 0 0" xyz="0 0 0"/>
        <mass value="2.0"/>
        <inertia ixx="0" ixy="0" ixz="0" iyy="0" iyz="0" izz="0"/>
      </inertial> 
      <visual name="shoulder_r">
        <origin xyz="-0.22 0 0" rpy="1.5708 0 0"/>
        <!-- <origin xyz="-0.08415 0 0" rpy="1.5708 0 0"/> -->
        <geometry>
          <mesh filename="meshes/shoulder_r.obj" scale="1.0 1.0 1.0"/>
        </geometry>
        <material name="color_01"/>
      </visual>
      <collision name="co_shoulder_r">
        <origin xyz="-0.22 0 0" rpy="1.5708 0 0"/>
        <geometry>
          <mesh filename="meshes/shoulder_r.obj" scale="1.0 1.0 1.0"/>
        </geometry>
      </collision>
    </link>

    <link name="link_arm_r_01">
      <inertial>
        <origin rpy="0 0 0" xyz="0 0 0"/>
        <mass value="4.0"/>
        <inertia ixx="0" ixy="0" ixz="0" iyy="0" iyz="0" izz="0"/>
      </inertial> 
      <visual name="arm_r_01">
        <origin xyz="-0.175 0 0.02" rpy="0 0 0"/>
        <!-- <origin xyz="-0.09523 -0.00406 -0.01136" rpy="1.5708 0 0"/> -->
        <geometry>
          <mesh filename="meshes/arm_r_01.obj" scale="1.0 1.0 1.0"/>
        </geometry>
        <material name="color_03"/>
      </visual>
      <collision name="co_arm_r_01">
        <origin xyz="-0.175 0 0.02" rpy="1.5708 0 0"/>
        <geometry>
          <mesh filename="meshes/arm_r_01.obj" scale="1.0 1.0 1.0"/>
        </geometry>
      </collision>
    </link>

    <link name="link_arm_r_02">
      <inertial>
        <origin rpy="0 0 0" xyz="0 0 0"/>
        <mass value="5.0"/>
        <inertia ixx="0" ixy="0" ixz="0" iyy="0" iyz="0" izz="0"/>
      </inertial> 
      <visual name="arm_r_02">
        <origin xyz="0.05 -0.10815 0.22" rpy="0 0 0"/>
        <!-- <origin xyz="-0.00213 -0.09054 -0.05436" rpy="1.5708 0 0"/> -->
        <geometry>
          <mesh filename="meshes/arm_r_02.obj" scale="1.0 1.0 1.0"/>
        </geometry>
        <material name="color_04"/>
      </visual>
      <collision name="co_arm_r_02">
        <origin xyz="-0.00679 -0.09681 -0.04815" rpy="1.5708 0 0"/>
        <geometry>
          <mesh filename="meshes/arm_r_02.obj" scale="1.0 1.0 1.0"/>
        </geometry>
      </collision>
    </link>

    <link name="link_arm_r_03">
      <inertial>
        <origin rpy="0 0 0" xyz="0 0 0"/>
        <mass value="5.0"/>
        <inertia ixx="0" ixy="0" ixz="0" iyy="0" iyz="0" izz="0"/>
      </inertial> 
      <visual name="arm_r_03">
        <origin xyz="0.02 0.01137 0.235" rpy="0 0 0"/>
        <!-- <origin xyz="-0.01526 -0.09395 0.00264" rpy="0 0 0"/> -->
        <geometry>
          <mesh filename="meshes/arm_r_03.obj" scale="1.0 1.0 1.0"/>
        </geometry>
        <material name="color_01"/>
      </visual>
      <collision name="co_arm_r_03">
        <origin xyz="0.02 0.01137 0.235" rpy="1.5708 0 0"/>
        <geometry>
          <mesh filename="meshes/arm_r_03.obj" scale="1.0 1.0 1.0"/>
        </geometry>
      </collision>
    </link>

    <link name="link_hand_r">
      <inertial>
        <origin rpy="0 0 0" xyz="0 0 0"/>
        <mass value="1.0"/>
        <inertia ixx="0" ixy="0" ixz="0" iyy="0" iyz="0" izz="0"/>
      </inertial> 
      <visual name="hand_r">
        <origin xyz="0.10738 0 0.07" rpy="0 0 0"/>
        <geometry>
          <mesh filename="meshes/hand_r.obj" scale="1.0 1.0 1.0"/>
        </geometry>
        <material name="color_04"/>
      </visual>
      <collision name="co_hand_r">
        <origin xyz="0.10738 0 0.07" rpy="1.5708 0 0"/>
        <geometry>
          <mesh filename="meshes/hand_r.obj" scale="1.0 1.0 1.0"/>
        </geometry>
      </collision>
    </link>

    <!-- ###### -->
    <link name="link_body">
      <inertial>
        <origin rpy="0 0 0" xyz="0 0 0"/>
        <mass value="10.0"/>
        <inertia ixx="0" ixy="0" ixz="0" iyy="0" iyz="0" izz="0"/>
      </inertial>   
      <visual name="body">
        <origin xyz="-0.02 0.11261 -0.3" rpy="0 0 0"/>
        <!-- <origin xyz="0.00114 0.1233 0.15401" rpy="0 0 0"/> -->
        <geometry>
          <mesh filename="meshes/body.obj" scale="1.0 1.0 1.0"/>
        </geometry>
        <material name="color_03"/>
      </visual>
      <collision name="co_body">
        <origin xyz="-0.02 0.11261 -0.3" rpy="0 0 0"/>
        <geometry>
          <mesh filename="meshes/body.obj" scale="1.0 1.0 1.0"/>
        </geometry>
      </collision>
    </link>

    <link name="link_hip">
      <inertial>
        <origin rpy="0 0 0" xyz="0 0 0"/>
        <mass value="5.0"/>
        <inertia ixx="0" ixy="0" ixz="0" iyy="0" iyz="0" izz="0"/>
      </inertial>   
      <visual name="hip">
        <origin xyz="0 0 0" rpy="0 0 0"/>
        <geometry>
          <mesh filename="meshes/hip.obj" scale="1.0 1.0 1.0"/>
        </geometry>
        <material name="color_01"/>
      </visual>
      <collision name="hip.001">
        <origin xyz="0 0 0" rpy="0 0 0"/>
        <geometry>
          <mesh filename="meshes/hip.obj" scale="1.0 1.0 1.0"/>
        </geometry>
      </collision>
    </link>

    <link name="link_hip_l">
      <inertial>
        <origin rpy="0 0 0" xyz="0 0 0"/>
        <mass value="0.5"/>
        <inertia ixx="0" ixy="0" ixz="0" iyy="0" iyz="0" izz="0"/>
      </inertial>   
      <visual name="hip_l">
        <origin xyz="0.24 -0.00043 -0.00096" rpy="0 0 0"/>
        <geometry>
          <mesh filename="meshes/hip_l.obj" scale="1.0 1.0 1.0"/>
        </geometry>
        <material name="color_03"/>
      </visual>
      <collision name="hip_l.001">
        <origin xyz="0.24 -0.00043 -0.00096" rpy="0 0 0"/>
        <geometry>
          <mesh filename="meshes/hip_l.obj" scale="1.0 1.0 1.0"/>
        </geometry>
      </collision>
    </link>

    <link name="link_leg_l_01">
      <inertial>
        <origin rpy="0 0 0" xyz="0 0 0"/>
        <mass value="2.0"/>
        <inertia ixx="0" ixy="0" ixz="0" iyy="0" iyz="0" izz="0"/>
      </inertial>   
      <visual name="leg_l_01">
        <origin xyz="0.17 -0.3849 0.45716" rpy="0 0 0"/>
        <geometry>
          <mesh filename="meshes/leg_l_01.obj" scale="1.0 1.0 1.0"/>
        </geometry>
        <material name="color_01"/>
      </visual>
      <collision name="leg_l_01.001">
        <origin xyz="0.17 -0.3849 0.45716" rpy="0 0 0"/>
        <geometry>
          <mesh filename="meshes/leg_l_01.obj" scale="1.0 1.0 1.0"/>
        </geometry>
      </collision>
    </link>

    <link name="link_leg_l_02">
      <inertial>
        <origin rpy="0 0 0" xyz="0 0 0"/>
        <mass value="2.0"/>
        <inertia ixx="0" ixy="0" ixz="0" iyy="0" iyz="0" izz="0"/>
      </inertial>   
      <visual name="leg_l_02">
        <origin xyz="0.17 0.09 -0.44" rpy="0 0 0"/>
        <geometry>
          <mesh filename="meshes/leg_l_02.obj" scale="1.0 1.0 1.0"/>
        </geometry>
        <material name="color_04"/>
      </visual>
      <collision name="leg_l_02.001">
        <origin xyz="0.17 0.09 -0.44" rpy="0 0 0"/>
        <geometry>
          <mesh filename="meshes/leg_l_02.obj" scale="1.0 1.0 1.0"/>
        </geometry>
      </collision>
    </link>

    <link name="link_leg_l_03">
      <inertial>
        <origin rpy="0 0 0" xyz="0 0 0"/>
        <mass value="2.0"/>
        <inertia ixx="0" ixy="0" ixz="0" iyy="0" iyz="0" izz="0"/>
      </inertial> 
      <visual name="leg_l_03">
        <origin xyz="0.17 -0.18418 0.03651" rpy="0 0 0"/>
        <geometry>
          <mesh filename="meshes/leg_l_03.obj" scale="1.0 1.0 1.0"/>
        </geometry>
        <material name="color_03"/>
      </visual>
      <collision name="leg_l_03.001">
        <origin xyz="0.17 -0.18418 0.03651" rpy="0 0 0"/>
        <geometry>
          <mesh filename="meshes/leg_l_03.obj" scale="1.0 1.0 1.0"/>
        </geometry>
      </collision>
    </link>

    <link name="link_foot_l">
      <inertial>
        <origin rpy="0 0 0" xyz="0 0 0"/>
        <mass value="4.0"/>
        <inertia ixx="0" ixy="0" ixz="0" iyy="0" iyz="0" izz="0"/>
      </inertial> 
      <visual name="foot_l">
        <origin xyz="0.17 -0.0175 0.132" rpy="0 0 0"/>
        <!-- <origin xyz="0.17 -0.00873 0.0849" rpy="0 0 0"/> -->
        <geometry>
          <mesh filename="meshes/foot_l.obj" scale="1.0 1.0 1.0"/>
        </geometry>
        <material name="color_01"/>
      </visual>
      <collision name="foot_l.001">
        <origin xyz="0.17 -0.0175 0.132" rpy="0 0 0"/>
        <geometry>
          <mesh filename="meshes/foot_l.obj" scale="1.0 1.0 1.0"/>
        </geometry>
      </collision>
    </link>

    <link name="link_hip_r">
      <inertial>
        <origin rpy="0 0 0" xyz="0 0 0"/>
        <mass value="0.5"/>
        <inertia ixx="0" ixy="0" ixz="0" iyy="0" iyz="0" izz="0"/>
      </inertial>       
      <visual name="hip_r">
        <origin xyz="-0.24 -0.00043 -0.00096" rpy="0 0 0"/>
        <geometry>
          <mesh filename="meshes/hip_r.obj" scale="1.0 1.0 1.0"/>
        </geometry>
        <material name="color_03"/>
      </visual>
      <collision name="hip_r.001">
        <origin xyz="-0.24 -0.00043 -0.00096" rpy="0 0 0"/>
        <geometry>
          <mesh filename="meshes/hip_r.obj" scale="1.0 1.0 1.0"/>
        </geometry>
      </collision>
    </link>

    <link name="link_leg_r_01">
      <inertial>
        <origin rpy="0 0 0" xyz="0 0 0"/>
        <mass value="2.0"/>
        <inertia ixx="0" ixy="0" ixz="0" iyy="0" iyz="0" izz="0"/>
      </inertial>   
      <visual name="leg_r_01">
        <origin xyz="-0.17 -0.384 0.45716" rpy="0 0 0"/>
        <geometry>
          <mesh filename="meshes/leg_r_01.obj" scale="1.0 1.0 1.0"/>
        </geometry>
        <material name="color_01"/>
      </visual>
      <collision name="leg_r_01.001">
        <origin xyz="-0.17 -0.384 0.45716" rpy="0 0 0"/>
        <geometry>
          <mesh filename="meshes/leg_r_01.obj" scale="1.0 1.0 1.0"/>
        </geometry>
      </collision>
    </link>

    <link name="link_leg_r_02">
      <inertial>
        <origin rpy="0 0 0" xyz="0 0 0"/>
        <mass value="2.0"/>
        <inertia ixx="0" ixy="0" ixz="0" iyy="0" iyz="0" izz="0"/>
      </inertial>   
      <visual name="leg_r_02">
        <origin xyz="-0.17 0.09 -0.44" rpy="0 0 0"/>
        <geometry>
          <mesh filename="meshes/leg_r_02.obj" scale="1.0 1.0 1.0"/>
        </geometry>
        <material name="color_04"/>
      </visual>
      <collision name="leg_r_02.001">
        <origin xyz="-0.17 0.09 -0.44" rpy="0 0 0"/>
        <geometry>
          <mesh filename="meshes/leg_r_02.obj" scale="1.0 1.0 1.0"/>
        </geometry>
      </collision>
    </link>

    <link name="link_leg_r_03">
      <inertial>
        <origin rpy="0 0 0" xyz="0 0 0"/>
        <mass value="3.0"/>
        <inertia ixx="0" ixy="0" ixz="0" iyy="0" iyz="0" izz="0"/>
      </inertial> 
      <visual name="leg_r_03">
        <origin xyz="-0.17 -0.19965 0.03957" rpy="0 0 0"/>
        <geometry>
          <mesh filename="meshes/leg_r_03.obj" scale="1.0 1.0 1.0"/>
        </geometry>
        <material name="color_03"/>
      </visual>
      <collision name="leg_r_03.001">
        <origin xyz="-0.17 -0.19965 0.03957" rpy="0 0 0"/>
        <geometry>
          <mesh filename="meshes/leg_r_03.obj" scale="1.0 1.0 1.0"/>
        </geometry>
      </collision>
    </link>

    <link name="link_foot_r">
      <inertial>
        <origin rpy="0 0 0" xyz="0 0 0"/>
        <mass value="4.0"/>
        <inertia ixx="0" ixy="0" ixz="0" iyy="0" iyz="0" izz="0"/>
      </inertial>    
      <visual name="foot_r">
        <origin xyz="-0.17 -0.0175 0.132" rpy="0 0 0"/>
        <!-- <origin xyz="-0.17 -0.00873 0.0849" rpy="0 0 0"/> -->
        <geometry>
          <mesh filename="meshes/foot_r.obj" scale="1.0 1.0 1.0"/>
        </geometry>
        <material name="color_01"/>
      </visual>
      <collision name="foot_r.001">
        <origin xyz="-0.17 -0.0175 0.132" rpy="0 0 0"/>
        <geometry>
          <mesh filename="meshes/foot_r.obj" scale="1.0 1.0 1.0"/>
        </geometry>
      </collision>
    </link>


<!-- joints -->
    <joint name="joint_baseLink_to_hip" type="fixed">
      <parent link="base_link"/>
      <child link="link_hip"/>
      <origin rpy="0 0 0" xyz="0 0 0."/>
      <axis xyz="0 0 1"/>
      <limit effort="300" velocity="10"/>
      <dynamics damping="0.5"/>
    </joint>  

    <joint name="joint_shoulder_l" type="revolute">
      <origin xyz="0.21646 0.3 0.00501" rpy="0 0 0"/>
      <!-- <origin xyz="0.09637 -0.00223 0.23495" rpy="0 0 0"/> -->
      <parent link="link_body"/>
      <child link="link_shoulder_l"/>
      <limit effort="300.0" velocity="20.0"/>
      <axis xyz="1 0 0"/>
      <dynamics damping="0.5"/> 
    </joint>

    <joint name="joint_arm_l_01" type="fixed">
      <origin xyz="0.30361 0 0" rpy="0 0 0"/>
      <parent link="link_shoulder_l"/>
      <child link="link_arm_l_01"/>
      <limit effort="300.0" velocity="20.0"/>
      <axis xyz="1 0 0"/>
      <dynamics damping="0.5"/> 
    </joint>

    <joint name="joint_arm_l_02" type="revolute">
      <origin xyz="0.21749 -0.18937 0" rpy="0 0 0"/>
      <!-- <origin xyz="0.09682 0 -0.1" rpy="0 0 0"/> -->
      <parent link="link_arm_l_01"/>
      <child link="link_arm_l_02"/>
      <limit effort="300.0" velocity="20.0"/>
      <axis xyz="0 1 0"/>
      <dynamics damping="0.5"/> 
    </joint>

    <joint name="joint_arm_l_03" type="revolute">
      <origin xyz="-0.0362  -0.17209 0.5047" rpy="0 0 0"/>
      <!-- <origin xyz="-0.01611 -0.22468 -0.07661" rpy="0 0 0"/> -->
      <parent link="link_arm_l_02"/>
      <child link="link_arm_l_03"/>
      <limit effort="300.0" velocity="20.0"/>
      <axis xyz="0 1 0"/>
      <dynamics damping="0.5"/> 
    </joint>

    <joint name="joint_hand_l" type="revolute">
      <origin xyz="0.06052 0.00296 0.72259" rpy="0 0 0"/>
      <!-- <origin xyz="0.02694 -0.32169 0.00132" rpy="0 0 0"/> -->
      <parent link="link_arm_l_03"/>
      <child link="link_hand_l"/>
      <limit effort="300.0" velocity="20.0"/>
      <axis xyz="0 0 1"/>
      <dynamics damping="0.5"/> 
    </joint>

    <joint name="joint_shoulder_r" type="revolute">
      <origin xyz="-0.21646 0.3 0.00501" rpy="0 0 0"/>
      <!-- <origin xyz="-0.09637 -0.00223 0.23495" rpy="0 0 0"/> -->
      <parent link="link_body"/>
      <child link="link_shoulder_r"/>
      <limit effort="300.0" velocity="20.0"/>
      <axis xyz="1 0 0"/>
      <dynamics damping="0.5"/> 
    </joint>

    <joint name="joint_arm_r_01" type="fixed">
      <origin xyz="-0.30361 0 0" rpy="0 0 0"/>
      <!-- <origin xyz="-0.13516 0 0" rpy="0 0 0"/> -->
      <parent link="link_shoulder_r"/>
      <child link="link_arm_r_01"/>
      <limit effort="300.0" velocity="20.0"/>
      <axis xyz="1 0 0"/>
      <dynamics damping="0.5"/> 
    </joint>

    <joint name="joint_arm_r_02" type="revolute">
      <origin xyz="-0.21749 -0.18937 0" rpy="0 0 0"/>
      <!-- <origin xyz="-0.09316 -1e-05 -0.0843" rpy="0 0 0"/> -->
      <parent link="link_arm_r_01"/>
      <child link="link_arm_r_02"/>
      <limit effort="300.0" velocity="20.0"/>
      <axis xyz="0 1 0"/>
      <dynamics damping="0.5"/> 
      <axis xyz="0 1 0"/>
      <dynamics damping="0.5"/> 
    </joint>

    <joint name="joint_arm_r_03" type="revolute">
      <origin xyz="0.0362  -0.17209 0.5047" rpy="0 0 0"/>
      <!-- <origin xyz="0.01245 -0.22467 -0.07661" rpy="0 0 0"/> -->
      <parent link="link_arm_r_02"/>
      <child link="link_arm_r_03"/>
      <limit effort="300.0" velocity="20.0"/>
      <axis xyz="0 1 0"/>
      <dynamics damping="0.5"/> 
    </joint>

    <joint name="joint_hand_r" type="revolute">
      <origin xyz="-0.06052 0.00296 0.72259" rpy="0 0 0"/>
      <parent link="link_arm_r_03"/>
      <child link="link_hand_r"/>
      <limit effort="300.0" velocity="20.0"/>
      <axis xyz="0 0 1"/>
      <dynamics damping="0.5"/> 
    </joint>

<!-- ### -->
    <joint name="joint_body" type="revolute">
      <origin xyz="0.03 0.54 0.03" rpy="0 0 0"/>
      <!-- <origin xyz="0 -0.00597 0.12515" rpy="0 0 0"/> -->
      <parent link="link_hip"/>
      <child link="link_body"/>
      <limit effort="300.0" velocity="20.0"/>
      <axis xyz="0 1 0"/>
      <dynamics damping="0.5"/>      
    </joint>

    <joint name="joint_hip_l" type="fixed">
      <origin xyz="0.03407 0.01131 0.00671" rpy="0 0 0"/>
      <parent link="link_hip"/>
      <child link="link_hip_l"/> 
      <limit effort="200.0" velocity="20.0"/>
      <axis xyz="1 0 0"/>
      <dynamics damping="0.5"/>
    </joint>

    <joint name="joint_leg_l_01" type="revolute">
      <origin xyz="0.19054 0 0" rpy="0 0 0"/>
      <parent link="link_hip_l"/>
      <child link="link_leg_l_01"/>
      <limit effort="200.0" velocity="20.0"/>
      <axis xyz="1 0 0"/>
      <dynamics damping="0.5"/>
    </joint>

    <joint name="joint_leg_l_02" type="revolute">
      <origin xyz="-0.00243 -0.55732 0.45859" rpy="0 0 0"/>
      <parent link="link_leg_l_01"/>
      <child link="link_leg_l_02"/>
      <limit effort="200.0" velocity="20.0"/>
      <axis xyz="1 0 0"/>
      <dynamics damping="0.5"/>
    </joint>

    <joint name="joint_leg_l_03" type="fixed">
      <origin xyz="0 0.127 -0.82" rpy="0 0 0"/>
      <parent link="link_leg_l_02"/>
      <child link="link_leg_l_03"/>
      <limit effort="200.0" velocity="20.0"/>
      <axis xyz="1 0 0"/>
      <dynamics damping="0.5"/>
    </joint>

    <joint name="joint_foot_l" type="revolute">
      <origin xyz="0 -0.6179 0.24035" rpy="0 0 0"/>
      <!-- <origin xyz="0 -0.107 -0.27508" rpy="0 0 0"/> -->
      <!-- <origin xyz="0 -0.59 0.279" rpy="0 0 0"/> -->
      <parent link="link_leg_l_03"/>
      <child link="link_foot_l"/>
      <limit effort="200.0" velocity="20.0"/>
      <axis xyz="1 0 0"/>
      <dynamics damping="0.5"/>      
    </joint>

    <joint name="joint_hip_r" type="fixed">
      <origin xyz="-0.03407 0.01131 0.00671" rpy="0 0 0"/>
      <parent link="link_hip"/>
      <child link="link_hip_r"/>
      <limit effort="200.0" velocity="20.0"/>
      <axis xyz="1 0 0"/>
      <dynamics damping="0.5"/>
    </joint>

    <joint name="joint_leg_r_01" type="revolute">
      <origin xyz="-0.19054 0 0" rpy="0 0 0"/>
      <parent link="link_hip_r"/>
      <child link="link_leg_r_01"/>
      <limit effort="200.0" velocity="20.0"/>
      <axis xyz="1 0 0"/>
      <dynamics damping="0.5"/>
    </joint>

    <joint name="joint_leg_r_02" type="revolute">
      <origin xyz="0.00243 -0.55732 0.45859" rpy="0 0 0"/>
      <parent link="link_leg_r_01"/>
      <child link="link_leg_r_02"/>
      <limit effort="200.0" velocity="20.0"/>
      <axis xyz="1 0 0"/>
      <dynamics damping="0.5"/>      
    </joint>

    <joint name="joint_leg_r_03" type="fixed">
      <origin xyz="0 0.127 -0.82" rpy="0 0 0"/>
      <parent link="link_leg_r_02"/>
      <child link="link_leg_r_03"/>
      <limit effort="200.0" velocity="20.0"/>
      <axis xyz="1 0 0"/>
      <dynamics damping="0.5"/>
    </joint>

    <joint name="joint_foot_r" type="revolute">
      <origin xyz="0 -0.6179 0.24035" rpy="0 0 0"/>
      <parent link="link_leg_r_03"/>
      <child link="link_foot_r"/>
      <limit effort="200.0" velocity="20.0"/>
      <axis xyz="1 0 0"/>
      <dynamics damping="0.5"/>
    </joint>

<!-- materials -->
    <material name="color_01">
      <color rgba="0.29476 0.75464 0.8 1.0"/>
    </material>

    <material name="color_02">
      <color rgba="0.45874 0.8 0.44927 1.0"/>
    </material>

    <material name="color_03">
      <color rgba="0.8 0.40416 0.54358 1.0"/>
    </material>

    <material name="color_04">
      <color rgba="0.8 0.69806 0.48693 1.0"/>
    </material>

  </robot>
